
## 错误处理与调试

### 错误处理

有一个良好的错误处理策略可以让用户知道到底发生了什么。为此，必须理解各种捕获和处理错误的方式

#### try/catch语句

```js
try {
  //可能出错的代码
  
} catch (error) {
  //出错时要做什么
}
```

如果try块中有代码发生错误，代码会立即推出执行，并跳到catch块中.catch块此时接受到一个对象，该对象包含发生错误的相关信息。错误对象中暴露的实际信息因浏览器而异，但至少包含错误信息的message属性

##### finally语句

try/catch语句中可选的finally语句始终执行，不论是try块中的代码是否执行错误

```js
function testFinally() {
  try {
    return 1
  } catch (error) {
    return 2
  }finally {
    return 0
  }
}
console.log(testFinally());
```
以上代码按道理不出错返回1，出错返回2，但是finally的存在导致这个函数始终会返回0

##### try/catch的用法

当try/catch中发生错误时，浏览器会认为错误被处理了，因此就不会使用机制报告错误。
try/catch最好用在自己无法控制的错误上。如果明确知道自己的代码会发生某种错误，那么久不适合使用try/catch

#### 抛出错误

与try/catch语句对应的一个机制是 throw 操作符，用于在任何时候抛出自定义错误.不限制数据类型

```js
throw 12345
throw "hello word"
throw true
throw {name: "javaScript"}
```

#### error事件

任何没有被try/catch语句处理的错误都会在window对象上触发error事件。

```js
window.onerror = (message, url, line)=>{
  console.log(message, url, line);
  //Uncaught ReferenceError: a is not defined 
  //file:///Users/weiwentao/studyEveryday/test/demo.html 
  //25
  return false
}
console.log(a);
```

**⚠️浏览器在使用这个事件处理错误时存在明显差异。在IE中发生error事件时，正常代码会继续执行，所有变量和数据会保持，且可以在onerror事件处理程序中访问。在Firefox中，正常代码的执行会终止，错误发生之前的所有变量和数据会被销毁，导致很难分析处理错误**




